Workbook
Name Slicer_Category: #N/A
Name Slicer_Gender: #N/A
Name Slicer_month: #N/A

Sheet pivot

Sheet Sales
A1: Order ID | B1: Date and Time | C1: Product ID | D1: Customer ID | E1: Category | F1: Payment Method | G1: Selling Price | H1: Quantity | I1: Total Sales | J1: Cost price | K1: profit | L1: days | M1: MONTH | N1: month name
A2: ORD1 | B2: 45431.301 | C2: PROD196 | D2: CUST480 | E2: Fashion | F2: Credit Card | G2: 1879.16 | H2: 9 | I2: =Sales[[#This Row],[Selling Price]]*H2 -> 16912.44 | J2: =VLOOKUP(Sales[[#This Row],[Product ID]],Products[],4,0) -> 487.84 | K2: =Sales[[#This Row],[Total Sales]]-Sales[[#This Row],[Cost price]] -> 16424.6 | L2: =TEXT(Sales[[#This Row],[Date and Time]],"dddd") -> Sunday | M2: =TEXT(Sales[[#This Row],[Date and Time]],"mm") -> 05 | N2: =TEXT(Sales[[#This Row],[Date and Time]],"mmmm") -> May
A3: ORD2 | B3: 45604.838 | C3: PROD52 | D3: CUST978 | E3: Electronics | F3: Credit Card | G3: 1564.59 | H3: 6 | I3: =Sales[[#This Row],[Selling Price]]*H3 -> 9387.54 | J3: =VLOOKUP(Sales[[#This Row],[Product ID]],Products[],4,0) -> 71.47 | K3: =Sales[[#This Row],[Total Sales]]-Sales[[#This Row],[Cost price]] -> 9316.07 | L3: =TEXT(Sales[[#This Row],[Date and Time]],"dddd") -> Friday | M3: =TEXT(Sales[[#This Row],[Date and Time]],"mm") -> 11 | N3: =TEXT(Sales[[#This Row],[Date and Time]],"mmmm") -> November
A4: ORD3 | B4: 45515.831 | C4: PROD128 | D4: CUST189 | E4: Home Appliances | F4: Bank Transfer | G4: 702.1 | H4: 9 | I4: =Sales[[#This Row],[Selling Price]]*H4 -> 6318.9 | J4: =VLOOKUP(Sales[[#This Row],[Product ID]],Products[],4,0) -> 505.04 | K4: =Sales[[#This Row],[Total Sales]]-Sales[[#This Row],[Cost price]] -> 5813.86 | L4: =TEXT(Sales[[#This Row],[Date and Time]],"dddd") -> Sunday | M4: =TEXT(Sales[[#This Row],[Date and Time]],"mm") -> 08 | N4: =TEXT(Sales[[#This Row],[Date and Time]],"mmmm") -> August
A5: ORD4 | B5: 45442.533 | C5: PROD126 | D5: CUST171 | E5: Electronics | F5: Debit Card | G5: 737.92 | H5: 6 | I5: =Sales[[#This Row],[Selling Price]]*H5 -> 4427.52 | J5: =VLOOKUP(Sales[[#This Row],[Product ID]],Products[],4,0) -> 605.3 | K5: =Sales[[#This Row],[Total Sales]]-Sales[[#This Row],[Cost price]] -> 3822.22 | L5: =TEXT(Sales[[#This Row],[Date and Time]],"dddd") -> Thursday | M5: =TEXT(Sales[[#This Row],[Date and Time]],"mm") -> 05 | N5: =TEXT(Sales[[#This Row],[Date and Time]],"mmmm") -> May
A6: ORD5 | B6: 45486.727 | C6: PROD65 | D6: CUST255 | E6: Toys | F6: PayPal | G6: 1749.17 | H6: 5 | I6: =Sales[[#This Row],[Selling Price]]*H6 -> 8745.85 | J6: =VLOOKUP(Sales[[#This Row],[Product ID]],Products[],4,0) -> 974.22 | K6: =Sales[[#This Row],[Total Sales]]-Sales[[#This Row],[Cost price]] -> 7771.63 | L6: =TEXT(Sales[[#This Row],[Date and Time]],"dddd") -> Saturday | M6: =TEXT(Sales[[#This Row],[Date and Time]],"mm") -> 07 | N6: =TEXT(Sales[[#This Row],[Date and Time]],"mmmm") -> July
A7: ORD6 | B7: 45582.724 | C7: PROD121 | D7: CUST552 | E7: Fashion | F7: PayPal | G7: 1706.03 | H7: 5 | I7: =Sales[[#This Row],[Selling Price]]*H7 -> 8530.15 | J7: =VLOOKUP(Sales[[#This Row],[Product ID]],Products[],4,0) -> 795.14 | K7: =Sales[[#This Row],[Total Sales]]-Sales[[#This Row],[Cost price]] -> 7735.01 | L7: =TEXT(Sales[[#This Row],[Date and Time]],"dddd") -> Thursday | M7: =TEXT(Sales[[#This Row],[Date and Time]],"mm") -> 10 | N7: =TEXT(Sales[[#This Row],[Date and Time]],"mmmm") -> October
A8: ORD7 | B8: 45420.238 | C8: PROD47 | D8: CUST814 | E8: Fashion | F8: Credit Card | G8: 646.26 | H8: 1 | I8: =Sales[[#This Row],[Selling Price]]*H8 -> 646.26 | J8: =VLOOKUP(Sales[[#This Row],[Product ID]],Products[],4,0) -> 821.78 | K8: =Sales[[#This Row],[Total Sales]]-Sales[[#This Row],[Cost price]] -> -175.52 | L8: =TEXT(Sales[[#This Row],[Date and Time]],"dddd") -> Wednesday | M8: =TEXT(Sales[[#This Row],[Date and Time]],"mm") -> 05 | N8: =TEXT(Sales[[#This Row],[Date and Time]],"mmmm") -> May
A9: ORD8 | B9: 45468.527 | C9: PROD2 | D9: CUST739 | E9: Toys | F9: Cash | G9: 1292.07 | H9: 10 | I9: =Sales[[#This Row],[Selling Price]]*H9 -> 12920.7 | J9: =VLOOKUP(Sales[[#This Row],[Product ID]],Products[],4,0) -> 253.61 | K9: =Sales[[#This Row],[Total Sales]]-Sales[[#This Row],[Cost price]] -> 12667.09 | L9: =TEXT(Sales[[#This Row],[Date and Time]],"dddd") -> Tuesday | M9: =TEXT(Sales[[#This Row],[Date and Time]],"mm") -> 06 | N9: =TEXT(Sales[[#This Row],[Date and Time]],"mmmm") -> June
A10: ORD9 | B10: 45593.676 | C10: PROD137 | D10: CUST920 | E10: Home Appliances | F10: Bank Transfer | G10: 125.1 | H10: 1 | I10: =Sales[[#This Row],[Selling Price]]*H10 -> 125.1 | J10: =VLOOKUP(Sales[[#This Row],[Product ID]],Products[],4,0) -> 612.42 | K10: =Sales[[#This Row],[Total Sales]]-Sales[[#This Row],[Cost price]] -> -487.32 | L10: =TEXT(Sales[[#This Row],[Date and Time]],"dddd") -> Monday | M10: =TEXT(Sales[[#This Row],[Date and Time]],"mm") -> 10 | N10: =TEXT(Sales[[#This Row],[Date and Time]],"mmmm") -> October
A11: ORD10 | B11: 45323.652 | C11: PROD136 | D11: CUST28 | E11: Books | F11: Debit Card | G11: 281.18 | H11: 6 | I11: =Sales[[#This Row],[Selling Price]]*H11 -> 1687.08 | J11: =VLOOKUP(Sales[[#This Row],[Product ID]],Products[],4,0) -> 226.52 | K11: =Sales[[#This Row],[Total Sales]]-Sales[[#This Row],[Cost price]] -> 1460.56 | L11: =TEXT(Sales[[#This Row],[Date and Time]],"dddd") -> Thursday | M11: =TEXT(Sales[[#This Row],[Date and Time]],"mm") -> 02 | N11: =TEXT(Sales[[#This Row],[Date and Time]],"mmmm") -> February
A12: ORD11 | B12: 45348.664 | C12: PROD104 | D12: CUST110 | E12: Books | F12: Bank Transfer | G12: 1247.8 | H12: 3 | I12: =Sales[[#This Row],[Selling Price]]*H12 -> 3743.4 | J12: =VLOOKUP(Sales[[#This Row],[Product ID]],Products[],4,0) -> 310.21 | K12: =Sales[[#This Row],[Total Sales]]-Sales[[#This Row],[Cost price]] -> 3433.19 | L12: =TEXT(Sales[[#This Row],[Date and Time]],"dddd") -> Monday | M12: =TEXT(Sales[[#This Row],[Date and Time]],"mm") -> 02 | N12: =TEXT(Sales[[#This Row],[Date and Time]],"mmmm") -> February
A13: ORD12 | B13: 45571.87 | C13: PROD165 | D13: CUST909 | E13: Books | F13: Credit Card | G13: 202.97 | H13: 1 | I13: =Sales[[#This Row],[Selling Price]]*H13 -> 202.97 | J13: =VLOOKUP(Sales[[#This Row],[Product ID]],Products[],4,0) -> 563.57 | K13: =Sales[[#This Row],[Total Sales]]-Sales[[#This Row],[Cost price]] -> -360.6 | L13: =TEXT(Sales[[#This Row],[Date and Time]],"dddd") -> Sunday | M13: =TEXT(Sales[[#This Row],[Date and Time]],"mm") -> 10 | N13: =TEXT(Sales[[#This Row],[Date and Time]],"mmmm") -> October
... A7001: ORD7000 | B7001: 45421.478 | C7001: PROD49 | D7001: CUST87 | E7001: Electronics | F7001: Debit Card | G7001: 1569.49 | H7001: 2 | I7001: =Sales[[#This Row],[Selling Price]]*H7001 -> 3138.98 | J7001: =VLOOKUP(Sales[[#This Row],[Product ID]],Products[],4,0) -> 401.98 | K7001: =Sales[[#This Row],[Total Sales]]-Sales[[#This Row],[Cost price]] -> 2737 | L7001: =TEXT(Sales[[#This Row],[Date and Time]],"dddd") -> Thursday | M7001: =TEXT(Sales[[#This Row],[Date and Time]],"mm") -> 05 | N7001: =TEXT(Sales[[#This Row],[Date and Time]],"mmmm") -> May
E7002: =COUNTA(Sales[Category]) -> 7000 | H7002: =SUBTOTAL(109,Sales[Quantity]) -> 38546 | I7002: =SUBTOTAL(109,Sales[Total Sales]) -> 38625342 | K7002: =SUBTOTAL(109,Sales[profit]) -> 35151031

Sheet Customer
A1: Customer ID | B1: Name | C1: Gender | D1: Age | E1: Country | F1: Continent | G1: City
A2: CUST1 | B2: Vicki Wright | C2: Female | D2: 26 | E2: Panama | F2: Europe | G2: Port John
A3: CUST2 | B3: Stephanie Castro | C3: Female | D3: 49 | E3: Madagascar | F3: North America | G3: Joshuafort
A4: CUST3 | B4: Ronald Graham | C4: Male | D4: 56 | E4: Cote d'Ivoire | F4: South America | G4: East Shannon
A5: CUST4 | B5: David White | C5: Female | D5: 60 | E5: United Arab Emirates | F5: Europe | G5: Omarmouth
A6: CUST5 | B6: Jerry Gonzalez | C6: Female | D6: 21 | E6: British Indian Ocean Territory (Chagos Archipelago) | F6: Europe | G6: New Maryside
A7: CUST6 | B7: John Jordan | C7: Male | D7: 56 | E7: Cameroon | F7: Africa | G7: South Ashley
A8: CUST7 | B8: Kevin Kaiser | C8: Female | D8: 34 | E8: Saint Barthelemy | F8: Asia | G8: Schmidthaven
A9: CUST8 | B9: Stacey Jimenez | C9: Male | D9: 39 | E9: Iraq | F9: North America | G9: Bennettview
A10: CUST9 | B10: Zachary Williams | C10: Male | D10: 60 | E10: Saint Vincent and the Grenadines | F10: South America | G10: Crawfordport
A11: CUST10 | B11: Casey Clark | C11: Male | D11: 28 | E11: Morocco | F11: Oceania | G11: Port Brandontown
A12: CUST11 | B12: James Mills | C12: Male | D12: 36 | E12: Palestinian Territory | F12: North America | G12: Lake Daltonton
A13: CUST12 | B13: Jared Johnson | C13: Male | D13: 36 | E13: Guatemala | F13: Asia | G13: Oscarberg
... A1001: CUST1000 | B1001: Samantha Wilkinson | C1001: Male | D1001: 57 | E1001: Nigeria | F1001: Asia | G1001: East Anthonyfort
A1002: =COUNTA(Customer[Customer ID]) -> 1000 | E1002: =COUNTA(Customer[Country]) -> 1000

Sheet Products
A1: Product ID | B1: Product Name | C1: Company | D1: Cost Price
A2: PROD1 | B2: Canon DSLR | C2: Dyson | D2: 435.29
A3: PROD2 | B3: Sony Headphones | C3: Samsung | D3: 253.61
A4: PROD3 | B4: Philips Air Fryer | C4: KitchenAid | D4: 27.63
A5: PROD4 | B5: Lego Star Wars Set | C5: Apple | D5: 454.08
A6: PROD5 | B6: Samsung Refrigerator | C6: Dyson | D6: 809.47
A7: PROD6 | B7: HP Printer | C7: Bose | D7: 96.13
A8: PROD7 | B8: Samsung Galaxy S22 | C8: IKEA | D8: 157.37
A9: PROD8 | B9: Apple Watch | C9: Asus | D9: 851.56
A10: PROD9 | B10: IKEA Chair | C10: Apple | D10: 481
A11: PROD10 | B11: Samsung Refrigerator | C11: HP | D11: 438.5
A12: PROD11 | B12: HP Printer | C12: Nike | D12: 595.51
A13: PROD12 | B13: Apple Watch | C13: Lego | D13: 132.39
... A201: PROD200 | B201: Sony Headphones | C201: Levi’s | D201: 606.07

Sheet Sheet2
A3: Row Labels | B3: Sum of Profit | C3: Sum of Sales
A4: 1 | B4: 159534.88 | C4: 171802.34
A5: 2 | B5: 134116.49 | C5: 146844.07
A6: 3 | B6: 71662.97 | C6: 80094.33
A7: 4 | B7: 71614.23 | C7: 76409.62
A8: 5 | B8: 89008.95 | C8: 98022.6
A9: 6 | B9: 105161.85 | C9: 114929.13
A10: 7 | B10: 160727.87 | C10: 171729.34
A11: 8 | B11: 104153.97 | C11: 113370.87
A12: 9 | B12: 79566.92 | C12: 88703.55
A13: 10 | B13: 102087.03 | C13: 111696.44
A14: 11 | B14: 39588.64 | C14: 42981.6
A15: Grand Total | B15: 1117223.8 | C15: 1216583.9
A18: Sum of Sales | B18: Column Labels | F18: E-Commerce Data Analytics
A19: Row Labels | B19: Female | C19: Male | D19: Grand Total
A20: Books | B20: 93981.13 | C20: 74909.52 | D20: 168890.65
A21: Electronics | B21: 101079.33 | C21: 107232.15 | D21: 208311.48
A22: Fashion | B22: 146387.87 | C22: 141048.81 | D22: 287436.68
A23: Home Appliances | B23: 150554.39 | C23: 167095.02 | D23: 317649.41
A24: Toys | B24: 116888.1 | C24: 117407.57 | D24: 234295.67
A25: Grand Total | B25: 608890.82 | C25: 607693.07 | D25: 1216583.9
A28: Row Labels | B28: Sum of Profit
A29: Books | B29: 152259.01
A30: Electronics | B30: 188126.2
A31: Fashion | B31: 266608.22
A32: Home Appliances | B32: 295158.75
A33: Toys | B33: 215071.62
A34: Grand Total | B34: 1117223.8
A37: Row Labels | B37: Sum of month
A38: PROD10 | B38: 7
A39: Grand Total | B39: 7
A240: Row Labels | B240: Count of Product ID
A241: Adidas | B241: 11
A242: Apple | B242: 16
A243: Asus | B243: 19
A244: Bose | B244: 11
A245: Canon | B245: 9
A246: Dell | B246: 6
A247: Dyson | B247: 9
A248: Fitbit | B248: 3
...

Sheet Sheet1
A1: Product ID | B1: Customer ID | C1: Category | D1: Gender | E1: Sales | F1: Profit | G1: month | H1: Month Name | I1: company
A2: PROD1 | B2: =VLOOKUP(A2,Sales[[Product ID]:[profit]],2,0) -> CUST125 | C2: =VLOOKUP(B2,Sales[[Customer ID]:[days]],2,0) -> Electronics | D2: =VLOOKUP(Sheet1!B2,Customer[[#Data],[#Totals]],3,0) -> Male | E2: {=VLOOKUP(A2,Sales[[Product ID]:[MONTH]],{7,9},0)} -> 9917.55 | F2: 9482.26 | G2: {=VLOOKUP(A2,Sales[[Product ID]:[month name]],{11,12},0)} -> 07 | H2: July | I2: =VLOOKUP(A2,Products[],3,0) -> Dyson
A3: PROD10 | B3: =VLOOKUP(A3,Sales[[Product ID]:[profit]],2,0) -> CUST138 | C3: =VLOOKUP(B3,Sales[[Customer ID]:[days]],2,0) -> Fashion | D3: =VLOOKUP(Sheet1!B3,Customer[[#Data],[#Totals]],3,0) -> Female | E3: {=VLOOKUP(A3,Sales[[Product ID]:[MONTH]],{7,9},0)} -> 5444.04 | F3: 5005.54 | G3: {=VLOOKUP(A3,Sales[[Product ID]:[month name]],{11,12},0)} -> 07 | H3: July | I3: =VLOOKUP(A3,Products[],3,0) -> HP
A4: PROD100 | B4: =VLOOKUP(A4,Sales[[Product ID]:[profit]],2,0) -> CUST419 | C4: =VLOOKUP(B4,Sales[[Customer ID]:[days]],2,0) -> Fashion | D4: =VLOOKUP(Sheet1!B4,Customer[[#Data],[#Totals]],3,0) -> Female | E4: {=VLOOKUP(A4,Sales[[Product ID]:[MONTH]],{7,9},0)} -> 8145.4 | F4: 7740.83 | G4: {=VLOOKUP(A4,Sales[[Product ID]:[month name]],{11,12},0)} -> 05 | H4: May | I4: =VLOOKUP(A4,Products[],3,0) -> Bose
A5: PROD101 | B5: =VLOOKUP(A5,Sales[[Product ID]:[profit]],2,0) -> CUST889 | C5: =VLOOKUP(B5,Sales[[Customer ID]:[days]],2,0) -> Toys | D5: =VLOOKUP(Sheet1!B5,Customer[[#Data],[#Totals]],3,0) -> Male | E5: {=VLOOKUP(A5,Sales[[Product ID]:[MONTH]],{7,9},0)} -> 278.95 | F5: -699.77 | G5: {=VLOOKUP(A5,Sales[[Product ID]:[month name]],{11,12},0)} -> 02 | H5: February | I5: =VLOOKUP(A5,Products[],3,0) -> Philips
A6: PROD102 | B6: =VLOOKUP(A6,Sales[[Product ID]:[profit]],2,0) -> CUST602 | C6: =VLOOKUP(B6,Sales[[Customer ID]:[days]],2,0) -> Home Appliances | D6: =VLOOKUP(Sheet1!B6,Customer[[#Data],[#Totals]],3,0) -> Male | E6: {=VLOOKUP(A6,Sales[[Product ID]:[MONTH]],{7,9},0)} -> 11118.18 | F6: 10823.35 | G6: {=VLOOKUP(A6,Sales[[Product ID]:[month name]],{11,12},0)} -> 01 | H6: January | I6: =VLOOKUP(A6,Products[],3,0) -> IKEA
A7: PROD103 | B7: =VLOOKUP(A7,Sales[[Product ID]:[profit]],2,0) -> CUST572 | C7: =VLOOKUP(B7,Sales[[Customer ID]:[days]],2,0) -> Home Appliances | D7: =VLOOKUP(Sheet1!B7,Customer[[#Data],[#Totals]],3,0) -> Female | E7: {=VLOOKUP(A7,Sales[[Product ID]:[MONTH]],{7,9},0)} -> 7947.42 | F7: 7058.34 | G7: {=VLOOKUP(A7,Sales[[Product ID]:[month name]],{11,12},0)} -> 06 | H7: June | I7: =VLOOKUP(A7,Products[],3,0) -> Asus
A8: PROD104 | B8: =VLOOKUP(A8,Sales[[Product ID]:[profit]],2,0) -> CUST110 | C8: =VLOOKUP(B8,Sales[[Customer ID]:[days]],2,0) -> Books | D8: =VLOOKUP(Sheet1!B8,Customer[[#Data],[#Totals]],3,0) -> Male | E8: {=VLOOKUP(A8,Sales[[Product ID]:[MONTH]],{7,9},0)} -> 3743.4 | F8: 3433.19 | G8: {=VLOOKUP(A8,Sales[[Product ID]:[month name]],{11,12},0)} -> 02 | H8: February | I8: =VLOOKUP(A8,Products[],3,0) -> KitchenAid
A9: PROD105 | B9: =VLOOKUP(A9,Sales[[Product ID]:[profit]],2,0) -> CUST695 | C9: =VLOOKUP(B9,Sales[[Customer ID]:[days]],2,0) -> Home Appliances | D9: =VLOOKUP(Sheet1!B9,Customer[[#Data],[#Totals]],3,0) -> Male | E9: {=VLOOKUP(A9,Sales[[Product ID]:[MONTH]],{7,9},0)} -> 14827.95 | F9: 14522.46 | G9: {=VLOOKUP(A9,Sales[[Product ID]:[month name]],{11,12},0)} -> 01 | H9: January | I9: =VLOOKUP(A9,Products[],3,0) -> Fitbit
A10: PROD106 | B10: =VLOOKUP(A10,Sales[[Product ID]:[profit]],2,0) -> CUST337 | C10: =VLOOKUP(B10,Sales[[Customer ID]:[days]],2,0) -> Electronics | D10: =VLOOKUP(Sheet1!B10,Customer[[#Data],[#Totals]],3,0) -> Female | E10: {=VLOOKUP(A10,Sales[[Product ID]:[MONTH]],{7,9},0)} -> 13593.3 | F10: 12843.11 | G10: {=VLOOKUP(A10,Sales[[Product ID]:[month name]],{11,12},0)} -> 11 | H10: November | I10: =VLOOKUP(A10,Products[],3,0) -> Bose
A11: PROD107 | B11: =VLOOKUP(A11,Sales[[Product ID]:[profit]],2,0) -> CUST948 | C11: =VLOOKUP(B11,Sales[[Customer ID]:[days]],2,0) -> Fashion | D11: =VLOOKUP(Sheet1!B11,Customer[[#Data],[#Totals]],3,0) -> Male | E11: {=VLOOKUP(A11,Sales[[Product ID]:[MONTH]],{7,9},0)} -> 11849.9 | F11: 11415.02 | G11: {=VLOOKUP(A11,Sales[[Product ID]:[month name]],{11,12},0)} -> 09 | H11: September | I11: =VLOOKUP(A11,Products[],3,0) -> Adidas
A12: PROD108 | B12: =VLOOKUP(A12,Sales[[Product ID]:[profit]],2,0) -> CUST82 | C12: =VLOOKUP(B12,Sales[[Customer ID]:[days]],2,0) -> Electronics | D12: =VLOOKUP(Sheet1!B12,Customer[[#Data],[#Totals]],3,0) -> Male | E12: {=VLOOKUP(A12,Sales[[Product ID]:[MONTH]],{7,9},0)} -> 3036.64 | F12: 2848.56 | G12: {=VLOOKUP(A12,Sales[[Product ID]:[month name]],{11,12},0)} -> 09 | H12: September | I12: =VLOOKUP(A12,Products[],3,0) -> Bose
A13: PROD109 | B13: =VLOOKUP(A13,Sales[[Product ID]:[profit]],2,0) -> CUST415 | C13: =VLOOKUP(B13,Sales[[Customer ID]:[days]],2,0) -> Home Appliances | D13: =VLOOKUP(Sheet1!B13,Customer[[#Data],[#Totals]],3,0) -> Female | E13: {=VLOOKUP(A13,Sales[[Product ID]:[MONTH]],{7,9},0)} -> 1206 | F13: 923.32 | G13: {=VLOOKUP(A13,Sales[[Product ID]:[month name]],{11,12},0)} -> 07 | H13: July | I13: =VLOOKUP(A13,Products[],3,0) -> Dell
... A201: PROD99 | B201: =VLOOKUP(A201,Sales[[Product ID]:[profit]],2,0) -> CUST302 | C201: =VLOOKUP(B201,Sales[[Customer ID]:[days]],2,0) -> Home Appliances | D201: =VLOOKUP(Sheet1!B201,Customer[[#Data],[#Totals]],3,0) -> Male | E201: {=VLOOKUP(A201,Sales[[Product ID]:[MONTH]],{7,9},0)} -> 19790.9 | F201: 19147.61 | G201: {=VLOOKUP(A201,Sales[[Product ID]:[month name]],{11,12},0)} -> 01 | H201: January | I201: =VLOOKUP(A201,Products[],3,0) -> Bose
